Workbook

Sheet ReadMe
B2: LankaKart Online Retail — Teaching Dataset
B3: Relational database sandbox for SQL practice · 8 tables · LKR pricing · Orders Jan 2025 – Sep 2026
B4: Each worksheet is one table. Import every sheet into the SQL sandbox as a table of the same name.
B6: TABLE DICTIONARY
B7: Table | C7: Description | D7: Rows | E7: Primary Key | F7: Foreign Keys
B8: Customers | C8: People who buy from the store | D8: 60 | E8: CustomerID | F8: —
B9: Products | C9: Catalogue of items for sale | D9: 56 | E9: ProductID | F9: CategoryID → Categories; SupplierID → Suppliers
B10: Categories | C10: Product groupings | D10: 8 | E10: CategoryID | F10: —
B11: Suppliers | C11: Companies that supply products | D11: 12 | E11: SupplierID | F11: —
B12: OrderHeader | C12: One row per customer order | D12: 220 | E12: OrderID | F12: CustomerID → Customers
B13: OrderItems | C13: One row per product line within an order | D13: 534 | E13: OrderItemID | F13: OrderID → OrderHeader; ProductID → Products
B14: Warehouses | C14: Physical stock locations | D14: 3 | E14: WarehouseID | F14: —
B15: Stock | C15: Quantity of each product held per warehouse | D15: 111 | E15: StockID | F15: ProductID → Products; WarehouseID → Warehouses
B17: HOW THE TABLES CONNECT (join map)
B18: Customers (1) ──< OrderHeader (many) on CustomerID
B19: OrderHeader (1) ──< OrderItems (many) on OrderID
B20: Products (1) ──< OrderItems (many) on ProductID
B21: Categories (1) ──< Products (many) on CategoryID
B22: Suppliers (1) ──< Products (many) on SupplierID
B23: Products (1) ──< Stock (many) >── (1) Warehouses — Stock resolves the many-to-many between Products and Warehouses
B25: TEACHING HOOKS BUILT INTO THE DATA
B26: • 8 customers have never placed an order — INNER JOIN vs LEFT JOIN (and NOT EXISTS) will give different customer counts.
B27: • 6 products have never been sold (incl. 2 discontinued) — find them with a LEFT JOIN from Products to OrderItems.
B28: • Supplier SUP-12 (Kandy Craft Collective) has no products yet — a LEFT JOIN from Suppliers shows it; INNER JOIN hides it.
B29: • Processing/Cancelled orders have a blank ShipDate — use IS NULL / IS NOT NULL.
... B38: • For Cancelled orders, OrderTotal_LKR reflects the order value at the time of cancellation.

Sheet Customers
A1: CustomerID | B1: FirstName | C1: LastName | D1: Gender | E1: Email | F1: Phone | G1: City | H1: District | I1: JoinDate
A2: CUST-1001 | B2: Ruwan | C2: Perera | D2: M | E2: ruwan.perera95@yahoo.com | F2: 072-2719583 | G2: Gampaha | H2: Gampaha | I2: 45155
A3: CUST-1002 | B3: Nethmi | C3: Amarasinghe | D3: M | E3: nethmi.amarasinghe5@gmail.com | F3: 074-9478454 | G3: Dehiwala | H3: Colombo | I3: 45150
A4: CUST-1003 | B4: Dulani | C4: Bandara | D4: F | E4: dulani.bandara92@outlook.com | F4: 077-4698379 | G4: Ratnapura | H4: Ratnapura | I4: 45485
A5: CUST-1004 | B5: Nethmi | C5: Herath | D5: M | E5: nethmi.herath1@gmail.com | F5: 076-5661907 | G5: Ratnapura | H5: Ratnapura | I5: 45359
A6: CUST-1005 | B6: Shalini | C6: Weerasinghe | D6: F | E6: shalini.weerasinghe14@gmail.com | F6: 076-6770619 | G6: Galle | H6: Galle | I6: 45026
A7: CUST-1006 | B7: Sanduni | C7: Wijesekara | D7: F | E7: sanduni.wijesekara59@outlook.com | F7: 071-5918715 | G7: Dehiwala | H7: Colombo | I7: 45314
A8: CUST-1007 | B8: Chathura | C8: Bandara | D8: M | E8: chathura.bandara91@gmail.com | F8: 074-5855124 | G8: Colombo | H8: Colombo | I8: 45604
A9: CUST-1008 | B9: Amaya | C9: Jayasinghe | D9: F | E9: amaya.jayasinghe49@yahoo.com | F9: 076-3728882 | G9: Matara | H9: Matara | I9: 45577
A10: CUST-1009 | B10: Arun | C10: Bandara | D10: M | E10: arun.bandara86@yahoo.com | F10: 071-3871230 | G10: Ratnapura | H10: Ratnapura | I10: 45626
A11: CUST-1010 | B11: Harsha | C11: Karunaratne | D11: M | E11: harsha.karunaratne49@yahoo.com | F11: 074-6440561 | G11: Anuradhapura | H11: Anuradhapura | I11: 45497
A12: CUST-1011 | B12: Amaya | C12: Fernando | D12: M | E12: amaya.fernando41@yahoo.com | F12: 074-6279418 | G12: Negombo | H12: Gampaha | I12: 44994
A13: CUST-1012 | B13: Menaka | C13: Senanayake | D13: F | E13: menaka.senanayake83@yahoo.com | F13: 072-5137722 | G13: Moratuwa | H13: Colombo | I13: 45198
... A61: CUST-1060 | B61: Kavindu | C61: Sivakumar | D61: F | E61: kavindu.sivakumar79@gmail.com | F61: 074-7442089 | G61: Matara | H61: Matara | I61: 45351

Sheet Products
A1: ProductID | B1: ProductName | C1: CategoryID | D1: SupplierID | E1: UnitPrice_LKR | F1: UnitCost_LKR | G1: ReorderLevel | H1: Discontinued
A2: PROD-101 | B2: Wireless Optical Mouse | C2: CAT-01 | D2: SUP-01 | E2: 4500 | F2: 3100 | G2: 25 | H2: No
A3: PROD-102 | B3: Mechanical Keyboard | C3: CAT-01 | D3: SUP-01 | E3: 18500 | F3: 13200 | G3: 15 | H3: No
A4: PROD-103 | B4: Bluetooth Earbuds Pro | C4: CAT-01 | D4: SUP-02 | E4: 12900 | F4: 8400 | G4: 15 | H4: No
A5: PROD-104 | B5: USB-C Fast Charger 45W | C5: CAT-01 | D5: SUP-02 | E5: 6800 | F5: 4300 | G5: 10 | H5: No
A6: PROD-105 | B6: Power Bank 20000mAh | C6: CAT-01 | D6: SUP-02 | E6: 11500 | F6: 7600 | G6: 10 | H6: No
A7: PROD-106 | B7: HD Webcam 1080p | C7: CAT-01 | D7: SUP-11 | E7: 13500 | F7: 9200 | G7: 25 | H7: No
A8: PROD-107 | B8: Smart Watch Fit-X | C8: CAT-01 | D8: SUP-11 | E8: 24500 | F8: 16800 | G8: 15 | H8: No
A9: PROD-108 | B9: Portable Bluetooth Speaker | C9: CAT-01 | D9: SUP-01 | E9: 15900 | F9: 10500 | G9: 15 | H9: No
A10: PROD-109 | B10: 32GB USB Flash Drive | C10: CAT-01 | D10: SUP-01 | E10: 2400 | F10: 1500 | G10: 30 | H10: No
A11: PROD-110 | B11: Laptop Cooling Pad | C11: CAT-01 | D11: SUP-02 | E11: 7200 | F11: 4700 | G11: 25 | H11: Yes
A12: PROD-111 | B12: Electric Rice Cooker 2.8L | C12: CAT-02 | D12: SUP-03 | E12: 14900 | F12: 10200 | G12: 10 | H12: No
A13: PROD-112 | B13: Non-stick Frying Pan 28cm | C13: CAT-02 | D13: SUP-03 | E13: 5600 | F13: 3500 | G13: 30 | H13: No
... A57: PROD-156 | B57: Kids Tricycle | C57: CAT-08 | D57: SUP-09 | E57: 14500 | F57: 9800 | G57: 20 | H57: No

Sheet Categories
A1: CategoryID | B1: CategoryName | C1: Description
A2: CAT-01 | B2: Electronics | C2: Consumer electronics, mobile accessories and gadgets
A3: CAT-02 | B3: Home & Kitchen | C3: Appliances, cookware and household items
A4: CAT-03 | B4: Fashion | C4: Clothing, footwear and accessories
A5: CAT-04 | B5: Groceries | C5: Packaged food and everyday essentials
A6: CAT-05 | B6: Health & Beauty | C6: Personal care, wellness and ayurvedic products
A7: CAT-06 | B7: Sports & Outdoor | C7: Sporting goods and outdoor equipment
A8: CAT-07 | B8: Books & Stationery | C8: Books, office and school supplies
A9: CAT-08 | B9: Toys & Kids | C9: Toys, games and children's items

Sheet Suppliers
A1: SupplierID | B1: SupplierName | C1: ContactPerson | D1: Phone | E1: Email | F1: City | G1: Country
A2: SUP-01 | B2: TechLanka Distributors | C2: Ruwan Jayasuriya | D2: 011-2547890 | E2: sales@techlanka.lk | F2: Colombo | G2: Sri Lanka
A3: SUP-02 | B3: Shenzhen Electronics Co. | C3: Li Wei | D3: +86-755-8830-1122 | E3: export@szelec.cn | F3: Shenzhen | G3: China
A4: SUP-03 | B4: Kitchen Craft Imports | C4: Dinesh Mendis | D4: 011-2698741 | E4: orders@kitchencraft.lk | F4: Colombo | G4: Sri Lanka
A5: SUP-04 | B5: Island Apparel (Pvt) Ltd | C5: Shalini Fonseka | D5: 031-2245678 | E5: info@islandapparel.lk | F5: Katunayake | G5: Sri Lanka
A6: SUP-05 | B6: Ceylon Fresh Foods | C6: Nuwan Ratnayake | D6: 066-2287654 | E6: supply@ceylonfresh.lk | F6: Dambulla | G6: Sri Lanka
A7: SUP-06 | B7: Ayur Ceylon Naturals | C7: Kumari Herath | D7: 081-2234567 | E7: hello@ayurceylon.lk | F7: Kandy | G7: Sri Lanka
A8: SUP-07 | B8: Colombo Sports Supply | C8: Roshan de Alwis | D8: 011-2876543 | E8: sales@colombosports.lk | F8: Colombo | G8: Sri Lanka
A9: SUP-08 | B9: Lanka Book House | C9: Priyantha Gamage | D9: 011-2334455 | E9: orders@lankabooks.lk | F9: Maradana | G9: Sri Lanka
A10: SUP-09 | B10: Little Stars Toys | C10: Fathima Rizna | D10: 011-2445566 | E10: contact@littlestars.lk | F10: Wellawatte | G10: Sri Lanka
A11: SUP-10 | B11: Mumbai Trade Links | C11: Anil Deshmukh | D11: +91-22-4098-7766 | E11: exports@mumbaitrade.in | F11: Mumbai | G11: India
A12: SUP-11 | B12: Global Gadget Hub | C12: Tan Wei Ming | D12: +65-6733-9090 | E12: sg@gadgethub.com | F12: Singapore | G12: Singapore
A13: SUP-12 | B13: Kandy Craft Collective | C13: Sunil Ekanayake | D13: 081-2298877 | E13: info@kandycraft.lk | F13: Kandy | G13: Sri Lanka

Sheet OrderHeader
A1: OrderID | B1: CustomerID | C1: OrderDate | D1: ShipDate | E1: OrderStatus | F1: PaymentMethod | G1: ShippingCity | H1: ShippingFee_LKR | I1: OrderTotal_LKR
A2: ORD-10188 | B2: CUST-1008 | C2: 45663 | D2: 45667 | E2: Delivered | F2: Mobile Wallet | G2: Galle | H2: 450 | I2: =SUMIFS(OrderItems!$F$2:$F$535,OrderItems!$B$2:$B$535,A2)+H2 -> 69540
A3: ORD-10154 | B3: CUST-1043 | C3: 45664 | E3: Processing | F3: Card | G3: Ratnapura | H3: 450 | I3: =SUMIFS(OrderItems!$F$2:$F$535,OrderItems!$B$2:$B$535,A3)+H3 -> 74300
A4: ORD-10110 | B4: CUST-1017 | C4: 45665 | D4: 45668 | E4: Shipped | F4: Mobile Wallet | G4: Batticaloa | H4: 600 | I4: =SUMIFS(OrderItems!$F$2:$F$535,OrderItems!$B$2:$B$535,A4)+H4 -> 15060
A5: ORD-10123 | B5: CUST-1003 | C5: 45668 | D5: 45672 | E5: Delivered | F5: Card | G5: Ratnapura | H5: 0 | I5: =SUMIFS(OrderItems!$F$2:$F$535,OrderItems!$B$2:$B$535,A5)+H5 -> 6555
A6: ORD-10203 | B6: CUST-1013 | C6: 45670 | D6: 45675 | E6: Delivered | F6: Bank Transfer | G6: Kandy | H6: 0 | I6: =SUMIFS(OrderItems!$F$2:$F$535,OrderItems!$B$2:$B$535,A6)+H6 -> 23700
A7: ORD-10216 | B7: CUST-1052 | C7: 45671 | D7: 45672 | E7: Delivered | F7: Bank Transfer | G7: Galle | H7: 0 | I7: =SUMIFS(OrderItems!$F$2:$F$535,OrderItems!$B$2:$B$535,A7)+H7 -> 15900
A8: ORD-10133 | B8: CUST-1029 | C8: 45674 | D8: 45678 | E8: Delivered | F8: Card | G8: Badulla | H8: 600 | I8: =SUMIFS(OrderItems!$F$2:$F$535,OrderItems!$B$2:$B$535,A8)+H8 -> 52400
A9: ORD-10166 | B9: CUST-1009 | C9: 45674 | D9: 45675 | E9: Shipped | F9: Cash on Delivery | G9: Ratnapura | H9: 450 | I9: =SUMIFS(OrderItems!$F$2:$F$535,OrderItems!$B$2:$B$535,A9)+H9 -> 15150
A10: ORD-10018 | B10: CUST-1019 | C10: 45688 | D10: 45693 | E10: Delivered | F10: Card | G10: Anuradhapura | H10: 450 | I10: =SUMIFS(OrderItems!$F$2:$F$535,OrderItems!$B$2:$B$535,A10)+H10 -> 69250
A11: ORD-10093 | B11: CUST-1055 | C11: 45689 | D11: 45692 | E11: Delivered | F11: Cash on Delivery | G11: Negombo | H11: 600 | I11: =SUMIFS(OrderItems!$F$2:$F$535,OrderItems!$B$2:$B$535,A11)+H11 -> 55937.5
A12: ORD-10167 | B12: CUST-1009 | C12: 45692 | D12: 45696 | E12: Delivered | F12: Bank Transfer | G12: Ratnapura | H12: 450 | I12: =SUMIFS(OrderItems!$F$2:$F$535,OrderItems!$B$2:$B$535,A12)+H12 -> 23737.5
A13: ORD-10201 | B13: CUST-1009 | C13: 45693 | D13: 45697 | E13: Delivered | F13: Mobile Wallet | G13: Ratnapura | H13: 450 | I13: =SUMIFS(OrderItems!$F$2:$F$535,OrderItems!$B$2:$B$535,A13)+H13 -> 56550
A14: ORD-10094 | B14: CUST-1018 | C14: 45694 | D14: 45695 | E14: Delivered | F14: Cash on Delivery | G14: Jaffna | H14: 450 | I14: =SUMIFS(OrderItems!$F$2:$F$535,OrderItems!$B$2:$B$535,A14)+H14 -> 14940
A15: ORD-10126 | B15: CUST-1048 | C15: 45694 | D15: 45698 | E15: Delivered | F15: Mobile Wallet | G15: Gampaha | H15: 350 | I15: =SUMIFS(OrderItems!$F$2:$F$535,OrderItems!$B$2:$B$535,A15)+H15 -> 98550
... A17: ORD-10072 | B17: CUST-1034 | C17: 45699 | D17: 45700 | E17: Delivered | F17: Cash on Delivery | G17: Kandy | H17: 450 | I17: =SUMIFS(OrderItems!$F$2:$F$535,OrderItems!$B$2:$B$535,A17)+H17 -> 5305
A18: ORD-10101 | B18: CUST-1040 | C18: 45700 | E18: Processing | F18: Cash on Delivery | G18: Kurunegala | H18: 350 | I18: =SUMIFS(OrderItems!$F$2:$F$535,OrderItems!$B$2:$B$535,A18)+H18 -> 83260
A19: ORD-10215 | B19: CUST-1053 | C19: 45700 | D19: 45703 | E19: Delivered | F19: Card | G19: Anuradhapura | H19: 350 | I19: =SUMIFS(OrderItems!$F$2:$F$535,OrderItems!$B$2:$B$535,A19)+H19 -> 32250
A20: ORD-10031 | B20: CUST-1008 | C20: 45702 | D20: 45706 | E20: Delivered | F20: Card | G20: Matara | H20: 0 | I20: =SUMIFS(OrderItems!$F$2:$F$535,OrderItems!$B$2:$B$535,A20)+H20 -> 6900
A21: ORD-10176 | B21: CUST-1053 | C21: 45703 | D21: 45706 | E21: Delivered | F21: Cash on Delivery | G21: Anuradhapura | H21: 350 | I21: =SUMIFS(OrderItems!$F$2:$F$535,OrderItems!$B$2:$B$535,A21)+H21 -> 34510
A22: ORD-10127 | B22: CUST-1039 | C22: 45705 | D22: 45710 | E22: Delivered | F22: Mobile Wallet | G22: Anuradhapura | H22: 350 | I22: =SUMIFS(OrderItems!$F$2:$F$535,OrderItems!$B$2:$B$535,A22)+H22 -> 30550
A23: ORD-10073 | B23: CUST-1058 | C23: 45710 | E23: Processing | F23: Bank Transfer | G23: Matara | H23: 450 | I23: =SUMIFS(OrderItems!$F$2:$F$535,OrderItems!$B$2:$B$535,A23)+H23 -> 6010
A24: ORD-10122 | B24: CUST-1006 | C24: 45711 | D24: 45715 | E24: Shipped | F24: Cash on Delivery | G24: Gampaha | H24: 350 | I24: =SUMIFS(OrderItems!$F$2:$F$535,OrderItems!$B$2:$B$535,A24)+H24 -> 26010
A25: ORD-10038 | B25: CUST-1003 | C25: 45713 | D25: 45715 | E25: Shipped | F25: Cash on Delivery | G25: Ratnapura | H25: 350 | I25: =SUMIFS(OrderItems!$F$2:$F$535,OrderItems!$B$2:$B$535,A25)+H25 -> 5950
A26: ORD-10107 | B26: CUST-1060 | C26: 45718 | D26: 45723 | E26: Delivered | F26: Mobile Wallet | G26: Matara | H26: 350 | I26: =SUMIFS(OrderItems!$F$2:$F$535,OrderItems!$B$2:$B$535,A26)+H26 -> 24950
A27: ORD-10076 | B27: CUST-1059 | C27: 45720 | D27: 45724 | E27: Delivered | F27: Bank Transfer | G27: Gampaha | H27: 0 | I27: =SUMIFS(OrderItems!$F$2:$F$535,OrderItems!$B$2:$B$535,A27)+H27 -> 49800
A28: ORD-10165 | B28: CUST-1018 | C28: 45721 | D28: 45725 | E28: Delivered | F28: Card | G28: Jaffna | H28: 600 | I28: =SUMIFS(OrderItems!$F$2:$F$535,OrderItems!$B$2:$B$535,A28)+H28 -> 8200
A29: ORD-10095 | B29: CUST-1056 | C29: 45725 | D29: 45730 | E29: Shipped | F29: Cash on Delivery | G29: Jaffna | H29: 0 | I29: =SUMIFS(OrderItems!$F$2:$F$535,OrderItems!$B$2:$B$535,A29)+H29 -> 12300
A30: ORD-10177 | B30: CUST-1001 | C30: 45725 | E30: Processing | F30: Cash on Delivery | G30: Gampaha | H30: 450 | I30: =SUMIFS(OrderItems!$F$2:$F$535,OrderItems!$B$2:$B$535,A30)+H30 -> 5500
A31: ORD-10142 | B31: CUST-1023 | C31: 45730 | D31: 45731 | E31: Delivered | F31: Card | G31: Anuradhapura | H31: 350 | I31: =SUMIFS(OrderItems!$F$2:$F$535,OrderItems!$B$2:$B$535,A31)+H31 -> 15405
A32: ORD-10069 | B32: CUST-1028 | C32: 45731 | E32: Cancelled | F32: Card | G32: Matara | H32: 450 | I32: =SUMIFS(OrderItems!$F$2:$F$535,OrderItems!$B$2:$B$535,A32)+H32 -> 10200
A33: ORD-10017 | B33: CUST-1011 | C33: 45735 | D33: 45738 | E33: Delivered | F33: Bank Transfer | G33: Negombo | H33: 450 | I33: =SUMIFS(OrderItems!$F$2:$F$535,OrderItems!$B$2:$B$535,A33)+H33 -> 14700
A34: ORD-10108 | B34: CUST-1043 | C34: 45736 | D34: 45739 | E34: Delivered | F34: Card | G34: Ratnapura | H34: 350 | I34: =SUMIFS(OrderItems!$F$2:$F$535,OrderItems!$B$2:$B$535,A34)+H34 -> 75545
A35: ORD-10134 | B35: CUST-1059 | C35: 45740 | D35: 45742 | E35: Delivered | F35: Mobile Wallet | G35: Gampaha | H35: 350 | I35: =SUMIFS(OrderItems!$F$2:$F$535,OrderItems!$B$2:$B$535,A35)+H35 -> 24850
A36: ORD-10129 | B36: CUST-1052 | C36: 45742 | D36: 45745 | E36: Delivered | F36: Card | G36: Galle | H36: 350 | I36: =SUMIFS(OrderItems!$F$2:$F$535,OrderItems!$B$2:$B$535,A36)+H36 -> 58550
A37: ORD-10187 | B37: CUST-1012 | C37: 45752 | E37: Processing | F37: Bank Transfer | G37: Moratuwa | H37: 450 | I37: =SUMIFS(OrderItems!$F$2:$F$535,OrderItems!$B$2:$B$535,A37)+H37 -> 7350
A38: ORD-10047 | B38: CUST-1003 | C38: 45755 | D38: 45757 | E38: Shipped | F38: Mobile Wallet | G38: Ratnapura | H38: 450 | I38: =SUMIFS(OrderItems!$F$2:$F$535,OrderItems!$B$2:$B$535,A38)+H38 -> 6530
A39: ORD-10157 | B39: CUST-1048 | C39: 45755 | D39: 45756 | E39: Shipped | F39: Cash on Delivery | G39: Gampaha | H39: 350 | I39: =SUMIFS(OrderItems!$F$2:$F$535,OrderItems!$B$2:$B$535,A39)+H39 -> 36350
A40: ORD-10015 | B40: CUST-1005 | C40: 45763 | E40: Cancelled | F40: Cash on Delivery | G40: Galle | H40: 450 | I40: =SUMIFS(OrderItems!$F$2:$F$535,OrderItems!$B$2:$B$535,A40)+H40 -> 37650
A41: ORD-10160 | B41: CUST-1007 | C41: 45764 | D41: 45765 | E41: Delivered | F41: Mobile Wallet | G41: Colombo | H41: 450 | I41: =SUMIFS(OrderItems!$F$2:$F$535,OrderItems!$B$2:$B$535,A41)+H41 -> 21150
...

Sheet OrderItems
A1: OrderItemID | B1: OrderID | C1: ProductID | D1: Quantity | E1: UnitPrice_LKR | F1: LineTotal_LKR
A2: ITM-50001 | B2: ORD-10001 | C2: PROD-131 | D2: 3 | E2: 690 | F2: =ROUND(D2*E2,2) -> 2070
A3: ITM-50002 | B3: ORD-10001 | C3: PROD-141 | D3: 1 | E3: 3900 | F3: =ROUND(D3*E3,2) -> 3900
A4: ITM-50003 | B4: ORD-10001 | C4: PROD-154 | D4: 1 | E4: 3400 | F4: =ROUND(D4*E4,2) -> 3400
A5: ITM-50004 | B5: ORD-10001 | C5: PROD-145 | D5: 2 | E5: 3600 | F5: =ROUND(D5*E5,2) -> 7200
A6: ITM-50005 | B6: ORD-10002 | C6: PROD-107 | D6: 1 | E6: 24500 | F6: =ROUND(D6*E6,2) -> 24500
A7: ITM-50006 | B7: ORD-10002 | C7: PROD-148 | D7: 1 | E7: 950 | F7: =ROUND(D7*E7,2) -> 950
A8: ITM-50007 | B8: ORD-10002 | C8: PROD-133 | D8: 1 | E8: 2150 | F8: =ROUND(D8*E8,2) -> 2150
A9: ITM-50008 | B9: ORD-10003 | C9: PROD-105 | D9: 2 | E9: 10925 | F9: =ROUND(D9*E9,2) -> 21850
A10: ITM-50009 | B10: ORD-10003 | C10: PROD-125 | D10: 2 | E10: 9310 | F10: =ROUND(D10*E10,2) -> 18620
A11: ITM-50010 | B11: ORD-10003 | C11: PROD-117 | D11: 4 | E11: 13900 | F11: =ROUND(D11*E11,2) -> 55600
A12: ITM-50011 | B12: ORD-10004 | C12: PROD-119 | D12: 1 | E12: 2450 | F12: =ROUND(D12*E12,2) -> 2450
A13: ITM-50012 | B13: ORD-10004 | C13: PROD-156 | D13: 5 | E13: 14500 | F13: =ROUND(D13*E13,2) -> 72500
... A535: ITM-50534 | B535: ORD-10220 | C535: PROD-109 | D535: 1 | E535: 2160 | F535: =ROUND(D535*E535,2) -> 2160

Sheet Warehouses
A1: WarehouseID | B1: WarehouseName | C1: City
A2: WH-01 | B2: Colombo Main Warehouse | C2: Colombo
A3: WH-02 | B3: Kandy Regional Warehouse | C3: Kandy
A4: WH-03 | B4: Galle Regional Warehouse | C4: Galle

Sheet Stock
A1: StockID | B1: ProductID | C1: WarehouseID | D1: QuantityOnHand | E1: LastStockTake
A2: STK-5001 | B2: PROD-101 | C2: WH-01 | D2: 161 | E2: 46247
A3: STK-5002 | B3: PROD-101 | C3: WH-02 | D3: 161 | E3: 46235
A4: STK-5003 | B4: PROD-102 | C4: WH-01 | D4: 233 | E4: 46239
A5: STK-5004 | B5: PROD-103 | C5: WH-01 | D5: 117 | E5: 46236
A6: STK-5005 | B6: PROD-103 | C6: WH-02 | D6: 0 | E6: 46255
A7: STK-5006 | B7: PROD-104 | C7: WH-01 | D7: 201 | E7: 46258
A8: STK-5007 | B8: PROD-104 | C8: WH-02 | D8: 149 | E8: 46242
A9: STK-5008 | B9: PROD-105 | C9: WH-01 | D9: 138 | E9: 46257
A10: STK-5009 | B10: PROD-106 | C10: WH-01 | D10: 68 | E10: 46250
A11: STK-5010 | B11: PROD-106 | C11: WH-03 | D11: 178 | E11: 46255
A12: STK-5011 | B12: PROD-107 | C12: WH-01 | D12: 161 | E12: 46236
A13: STK-5012 | B13: PROD-107 | C13: WH-02 | D13: 0 | E13: 46264
... A112: STK-5111 | B112: PROD-156 | C112: WH-03 | D112: 215 | E112: 46256
